Workbook

Sheet Movie Data Base by Keizar
A1: Película | B1: Año | C1: Década | D1: Duración | E1: Director | F1: IMDb | G1: Mi nota | H1: Votos | I1: País | J1: Género | K1: Subgénero | L1: VOD (04/10/2026) | M1: Sinopsis | N1: Óscars | O1: Óscar Peli | P1: Óscar Dir. | Q1: Nom. Óscar | R1: Festivales | S1: Globo Oro | T1: S&S | U1: Puntos premios | V1: Importancia histórica | W1: Rank J.Wild | X1: Top150 XXI | Y1: IMDb ID
A2: La vida es bella | B2: 1997 | C2: 1990s | D2: 116 | E2: Roberto Benigni | F2: 8.6 | G2: 9 | H2: 819784 | I2: Italia | J2: Romance | K2: Comedia | M2: Un padre utiliza humor para proteger a su hijo en un campo nazi. | N2: 3 | O2: 0 | P2: 0 | Q2: 7 | R2: 0 | S2: 0 | U2: =O2*4 + P2*2 + MAX(0,N2-O2-P2)*1 + Q2*0.2 + R2*2 + S2*1 + IF(T2="",0,IF(T2<=10,8,IF(T2<=50,6,IF(T2<=100,4,2)))) -> 4.4 | V2: La vida es bella (1997) popularizó una aproximación agridulce al Holocausto, combinando humor y tragedia de. | Y2: tt0118799
A3: El señor de los anillos: El retorno del rey | B3: 2003 | C3: 2000s | D3: 201 | E3: Peter Jackson | F3: 9 | G3: 10 | H3: 2184685 | I3: EE.UU., Nueva Zelanda | J3: Fantasía | K3: Aventura | L3: Disney+, Movistar Plus+ Ficción Total , HBO Max, HBO Max Amazon Channel | M3: La batalla final contra Sauron mientras Frodo llega al Monte del Destino. | N3: 11 | O3: 1 | P3: 1 | Q3: 11 | R3: 0 | S3: 1 | U3: =O3*4 + P3*2 + MAX(0,N3-O3-P3)*1 + Q3*0.2 + R3*2 + S3*1 + IF(T3="",0,IF(T3<=10,8,IF(T3<=50,6,IF(T3<=100,4,2)))) -> 18.2 | V3: El retorno del Rey (2003) marcó un antes y un después en la fantasía épica cinematográfica, culminando una. | Y3: tt0167260
A4: La lista de Schindler | B4: 1993 | C4: 1990s | D4: 196 | E4: Steven Spielberg | F4: 9 | H4: 1597609 | I4: EE.UU. | J4: Drama | K4: Biográfico | M4: Oskar Schindler salva a cientos de judíos durante el Holocausto. | N4: 7 | O4: 1 | P4: 1 | Q4: 12 | R4: 0 | S4: 1 | U4: =O4*4 + P4*2 + MAX(0,N4-O4-P4)*1 + Q4*0.2 + R4*2 + S4*1 + IF(T4="",0,IF(T4<=10,8,IF(T4<=50,6,IF(T4<=100,4,2)))) -> 14.4 | V4: La lista de Schindler (1993) es uno de los retratos más potentes del Holocausto, clave en la memoria. | Y4: tt0108052
A5: Pulp Fiction | B5: 1994 | C5: 1990s | D5: 154 | E5: Quentin Tarantino | F5: 8.8 | G5: 9 | H5: 2458225 | I5: EE.UU. | J5: Drama | K5: Crimen | L5: Movistar Plus+ Ficción Total , HBO Max, HBO Max Amazon Channel | M5: Historias cruzadas de sicarios, un boxeador y una cita. | N5: 1 | O5: 0 | P5: 0 | Q5: 7 | R5: 1 | S5: 0 | T5: 129 | U5: =O5*4 + P5*2 + MAX(0,N5-O5-P5)*1 + Q5*0.2 + R5*2 + S5*1 + IF(T5="",0,IF(T5<=10,8,IF(T5<=50,6,IF(T5<=100,4,2)))) -> 6.4 | V5: Popularizó la narrativa fragmentada y no lineal, el diálogo pop y revitalizó el cine independiente de los 90. | W5: TOP 30-40 | Y5: tt0110912
A6: El padrino | B6: 1972 | C6: 1970s | D6: 175 | E6: Francis F. Coppola | F6: 9.2 | G6: 9 | H6: 2247164 | I6: EE.UU. | J6: Drama | K6: Crimen | L6: Netflix, Movistar Plus+ Ficción Total , Filmin, SkyShowtime | M6: Una familia mafiosa y el hijo que no quería heredarla. | N6: 3 | O6: 1 | P6: 0 | Q6: 11 | R6: 0 | S6: 1 | T6: 12 | U6: =O6*4 + P6*2 + MAX(0,N6-O6-P6)*1 + Q6*0.2 + R6*2 + S6*1 + IF(T6="",0,IF(T6<=10,8,IF(T6<=50,6,IF(T6<=100,4,2)))) -> 15.2 | V6: El padrino (1972) fijó el canon del cine de mafia moderno, con un equilibrio perfecto entre drama familiar y. | W6: TOP 30-40 | Y6: tt0068646
A7: Cadena perpetua | B7: 1994 | C7: 1990s | D7: 142 | E7: Frank Darabont | F7: 9.3 | G7: 9 | H7: 3223946 | I7: EE.UU. | J7: Drama | L7: Prime, Movistar Plus+ Ficción Total , HBO Max, HBO Max Amazon Channel | M7: La amistad entre dos presos condenados y su lucha por la esperanza en prisión. | N7: 0 | O7: 0 | P7: 0 | Q7: 7 | R7: 0 | S7: 0 | U7: =O7*4 + P7*2 + MAX(0,N7-O7-P7)*1 + Q7*0.2 + R7*2 + S7*1 + IF(T7="",0,IF(T7<=10,8,IF(T7<=50,6,IF(T7<=100,4,2)))) -> 1.4 | V7: Cadena perpetua (1994) se ha convertido con los años en un clásico moderno sobre esperanza y amistad en la. | Y7: tt0111161
A8: Million Dollar Baby | B8: 2004 | C8: 2000s | D8: 132 | E8: Clint Eastwood | F8: 8.1 | H8: 771297 | I8: EE.UU. | J8: Drama | K8: Deportivo | L8: Prime, Movistar, Movistar Plus+ Ficción Total , HBO Max, Acontra, HBO Max Amazon Channel | M8: Un entrenador veterano forma a una boxeadora tardía. | N8: 4 | O8: 1 | P8: 1 | Q8: 7 | R8: 0 | S8: 0 | U8: =O8*4 + P8*2 + MAX(0,N8-O8-P8)*1 + Q8*0.2 + R8*2 + S8*1 + IF(T8="",0,IF(T8<=10,8,IF(T8<=50,6,IF(T8<=100,4,2)))) -> 9.4 | V8: Ganó cuatro Óscars y reabrió el debate sobre la eutanasia. | X8: 66 | Y8: tt0405159
A9: American History X | B9: 1998 | C9: 1990s | D9: 119 | E9: Tony Kaye | F9: 8.5 | G9: 8 | H9: 1282562 | I9: EE.UU. | J9: Drama | K9: Carcelario | L9: 3Cat | M9: Un neonazi reformado intenta evitar que su hermano siga sus pasos. | N9: 0 | O9: 0 | P9: 0 | Q9: 1 | R9: 0 | S9: 0 | U9: =O9*4 + P9*2 + MAX(0,N9-O9-P9)*1 + Q9*0.2 + R9*2 + S9*1 + IF(T9="",0,IF(T9<=10,8,IF(T9<=50,6,IF(T9<=100,4,2)))) -> 0.2 | V9: American History X (1998) es una de las representaciones más intensas del odio racial y la radicalización. | Y9: tt0120586
A10: El pianista | B10: 2002 | C10: 2000s | D10: 150 | E10: Roman Polanski | F10: 8.5 | G10: 8 | H10: 1020984 | I10: Francia, Polonia | J10: Musical | K10: Biográfico | L10: Prime, Disney+, Movistar, Movistar Plus+ Ficción Total , FlixOlé, FlixOlé Amazon Channel | M10: Un pianista judío lucha por sobrevivir durante el Holocausto. | N10: 3 | O10: 0 | P10: 1 | Q10: 7 | R10: 1 | S10: 0 | U10: =O10*4 + P10*2 + MAX(0,N10-O10-P10)*1 + Q10*0.2 + R10*2 + S10*1 + IF(T10="",0,IF(T10<=10,8,IF(T10<=50,6,IF(T10<=100,4,2)))) -> 7.4 | V10: El pianista (2002) es uno de los grandes retratos sobrios del Holocausto, centrado en la supervivencia. | Y10: tt0253474
A11: Luces de la ciudad | B11: 1931 | C11: 1930s | D11: 87 | E11: Charles Chaplin | F11: 8.5 | H11: 217749 | I11: EE.UU. | J11: Romance | K11: Comedia | L11: Acontra, Acontra Plus Amazon Channel | M11: Chaplin interpreta a un vagabundo enamorado de una florista ciega. | N11: 0 | O11: 0 | P11: 0 | Q11: 0 | R11: 0 | S11: 0 | T11: 36 | U11: =O11*4 + P11*2 + MAX(0,N11-O11-P11)*1 + Q11*0.2 + R11*2 + S11*1 + IF(T11="",0,IF(T11<=10,8,IF(T11<=50,6,IF(T11<=100,4,2)))) -> 6 | V11: Luces de la ciudad (1931) representa la fusión perfecta del slapstick de Chaplin con un profundo componente. | Y11: tt0021749
A12: Gran Torino | B12: 2008 | C12: 2000s | D12: 116 | E12: Clint Eastwood | F12: 8.1 | G12: 8 | H12: 867929 | I12: EE.UU. | J12: Drama | K12: Mafia | L12: Prime, Movistar, Movistar Plus+ Ficción Total , HBO Max, HBO Max Amazon Channel | M12: Un veterano se enfrenta a sus prejuicios y entabla amistad con un joven hmong. | N12: 0 | O12: 0 | P12: 0 | Q12: 0 | R12: 0 | S12: 0 | U12: =O12*4 + P12*2 + MAX(0,N12-O12-P12)*1 + Q12*0.2 + R12*2 + S12*1 + IF(T12="",0,IF(T12<=10,8,IF(T12<=50,6,IF(T12<=100,4,2)))) -> 0 | V12: Gran Torino (2008) es considerada una obra clave del cine de su época, y una pieza importante en la. | Y12: tt1205489
A13: Terminator | B13: 1984 | C13: 1980s | D13: 107 | E13: James Cameron | F13: 8.1 | G13: 7 | H13: 1013987 | I13: EE.UU. | J13: Ciencia ficción | K13: Acción | L13: Prime | M13: Un cyborg asesino llega del futuro para matar a Sarah Connor, cuyo hijo aún no nacido será. | N13: 0 | O13: 0 | P13: 0 | Q13: 0 | R13: 0 | S13: 0 | U13: =O13*4 + P13*2 + MAX(0,N13-O13-P13)*1 + Q13*0.2 + R13*2 + S13*1 + IF(T13="",0,IF(T13<=10,8,IF(T13<=50,6,IF(T13<=100,4,2)))) -> 0 | Y13: tt0088247
A14: El padrino. Parte II | B14: 1974 | C14: 1970s | D14: 202 | E14: Francis F. Coppola | F14: 9 | G14: 10 | H14: 1507335 | I14: EE.UU. | J14: Drama | K14: Crimen | L14: Netflix, Movistar Plus+ Ficción Total , Filmin, SkyShowtime | M14: Michael consolida su poder mientras se cuenta el ascenso de su padre. | N14: 6 | O14: 1 | P14: 1 | Q14: 11 | R14: 0 | S14: 0 | T14: 104 | U14: =O14*4 + P14*2 + MAX(0,N14-O14-P14)*1 + Q14*0.2 + R14*2 + S14*1 + IF(T14="",0,IF(T14<=10,8,IF(T14<=50,6,IF(T14<=100,4,2)))) -> 14.2 | V14: El padrino. | W14: #6 | Y14: tt0071562
A15: Harakiri | B15: 1962 | C15: 1960s | D15: 133 | E15: Masaki Kobayashi | F15: 8.6 | H15: 93309 | I15: Japón | J15: Drama | K15: Misterio | L15: Prime, Filmin, Acontra | M15: Un samurái sin señor pide morir en casa de un clan. | N15: 0 | O15: 0 | P15: 0 | Q15: 0 | R15: 0 | S15: 0 | U15: =O15*4 + P15*2 + MAX(0,N15-O15-P15)*1 + Q15*0.2 + R15*2 + S15*1 + IF(T15="",0,IF(T15<=10,8,IF(T15<=50,6,IF(T15<=100,4,2)))) -> 0 | V15: Harakiri (1962) es considerada una obra clave del género drama, samurai, y una pieza importante en la. | W15: TOP 30-40 | Y15: tt0056058
A16: Reservoir Dogs | B16: 1992 | C16: 1990s | D16: 99 | E16: Quentin Tarantino | F16: 8.2 | G16: 8 | H16: 1178280 | I16: EE.UU. | J16: Thriller | K16: Atracos | L16: Filmin, Lionsgate+ Amazon Channel | M16: Criminales sospechan que uno de ellos es un infiltrado tras un atraco fallido. | N16: 0 | O16: 0 | P16: 0 | Q16: 0 | R16: 0 | S16: 0 | U16: =O16*4 + P16*2 + MAX(0,N16-O16-P16)*1 + Q16*0.2 + R16*2 + S16*1 + IF(T16="",0,IF(T16<=10,8,IF(T16<=50,6,IF(T16<=100,4,2)))) -> 0 | V16: Reservoir Dogs (1992) supuso la irrupción de Tarantino y redefinió el cine independiente de los 90 con su. | Y16: tt0105236
A17: Ciudad de Dios | B17: 2002 | C17: 2000s | D17: 130 | E17: Fernando Meirelles | F17: 8.6 | G17: 10 | H17: 878822 | I17: Brasil | J17: Drama | K17: Crimen | L17: Movistar, Movistar Plus+ Ficción Total , Acontra, Acontra Plus Amazon Channel, Runtime | M17: Dos chavales de una favela: uno fotógrafo, otro narco. | N17: 0 | O17: 0 | P17: 0 | Q17: 4 | R17: 0 | S17: 0 | U17: =O17*4 + P17*2 + MAX(0,N17-O17-P17)*1 + Q17*0.2 + R17*2 + S17*1 + IF(T17="",0,IF(T17<=10,8,IF(T17<=50,6,IF(T17<=100,4,2)))) -> 0.8 | V17: Ciudad de Dios (2002) revolucionó el cine de barrio marginal con un estilo visual eléctrico y montaje. | W17: Casi top | Y17: tt0317248
A18: Psicosis | B18: 1960 | C18: 1960s | D18: 109 | E18: Alfred Hitchcock | F18: 8.5 | G18: 8 | H18: 791672 | I18: EE.UU. | J18: Terror | K18: Misterio | M18: Una joven desaparece tras robar dinero y termina en un motel regentado por Norman Bates. | N18: 0 | O18: 0 | P18: 0 | Q18: 4 | R18: 0 | S18: 0 | T18: 31 | U18: =O18*4 + P18*2 + MAX(0,N18-O18-P18)*1 + Q18*0.2 + R18*2 + S18*1 + IF(T18="",0,IF(T18<=10,8,IF(T18<=50,6,IF(T18<=100,4,2)))) -> 6.8 | V18: Psicosis (1960) es considerada una obra clave del género terror, thriller, y una pieza importante en la. | Y18: tt0054215
A19: La chaqueta metálica | B19: 1987 | C19: 1980s | D19: 116 | E19: Stanley Kubrick | F19: 8.2 | H19: 856754 | I19: EE.UU., Reino Unido | J19: Bélico | K19: Drama | L19: Movistar, Movistar Plus+ Ficción Total , HBO Max, HBO Max Amazon Channel | M19: Reclutas marines viven un entrenamiento brutal antes del combate. | N19: 0 | O19: 0 | P19: 0 | Q19: 1 | R19: 0 | S19: 0 | U19: =O19*4 + P19*2 + MAX(0,N19-O19-P19)*1 + Q19*0.2 + R19*2 + S19*1 + IF(T19="",0,IF(T19<=10,8,IF(T19<=50,6,IF(T19<=100,4,2)))) -> 0.2 | V19: La chaqueta metálica (1987) es considerada una obra clave del cine de su época, y una pieza importante en la. | Y19: tt0093058
A20: Réquiem por un sueño | B20: 2000 | C20: 2000s | D20: 102 | E20: Darren Aronofsky | F20: 8.3 | H20: 981736 | I20: EE.UU. | J20: Drama | L20: Lionsgate+ Amazon Channel | M20: Harry (Jared Leto) y su madre (Ellen Burstyn) tienen sueños muy distintos: ella está. | N20: 0 | O20: 0 | P20: 0 | Q20: 1 | R20: 0 | S20: 0 | U20: =O20*4 + P20*2 + MAX(0,N20-O20-P20)*1 + Q20*0.2 + R20*2 + S20*1 + IF(T20="",0,IF(T20<=10,8,IF(T20<=50,6,IF(T20<=100,4,2)))) -> 0.2 | Y20: tt0180093
A21: Taxi Driver | B21: 1976 | C21: 1970s | D21: 114 | E21: Martin Scorsese | F21: 8.2 | G21: 8 | H21: 1037580 | I21: EE.UU. | J21: Drama | K21: Crimen | L21: Movistar, Movistar Plus+ Ficción Total , Filmin | M21: Un taxista insomne se obsesiona con limpiar Nueva York. | N21: 0 | O21: 0 | P21: 0 | Q21: 4 | R21: 1 | S21: 0 | T21: 29 | U21: =O21*4 + P21*2 + MAX(0,N21-O21-P21)*1 + Q21*0.2 + R21*2 + S21*1 + IF(T21="",0,IF(T21<=10,8,IF(T21<=50,6,IF(T21<=100,4,2)))) -> 8.8 | V21: Cima del Nuevo Hollywood: el antihéroe urbano alienado y la violencia como catarsis, con el Nueva York. | W21: #9 | Y21: tt0075314
A22: Una mente maravillosa | B22: 2001 | C22: 2000s | D22: 135 | E22: Ron Howard | F22: 8.2 | H22: 1060822 | I22: EE.UU. | J22: Drama | K22: Misterio | M22: Obsesionado con la búsqueda de una idea matemática original, el brillante estudiante John. | N22: 4 | O22: 1 | P22: 1 | Q22: 8 | R22: 0 | S22: 1 | U22: =O22*4 + P22*2 + MAX(0,N22-O22-P22)*1 + Q22*0.2 + R22*2 + S22*1 + IF(T22="",0,IF(T22<=10,8,IF(T22<=50,6,IF(T22<=100,4,2)))) -> 10.6 | Y22: tt0268978
A23: Cisne negro | B23: 2010 | C23: 2010s | D23: 108 | E23: Darren Aronofsky | F23: 8 | H23: 895252 | I23: EE.UU. | J23: Thriller | K23: Drama | L23: Disney+ | M23: Nina (Natalie Portman), una brillante bailarina que forma parte de una compañía de ballet de. | N23: 1 | O23: 0 | P23: 0 | Q23: 5 | R23: 0 | S23: 0 | U23: =O23*4 + P23*2 + MAX(0,N23-O23-P23)*1 + Q23*0.2 + R23*2 + S23*1 + IF(T23="",0,IF(T23<=10,8,IF(T23<=50,6,IF(T23<=100,4,2)))) -> 2 | Y23: tt0947798
A24: Uno de los nuestros | B24: 1990 | C24: 1990s | D24: 145 | E24: Martin Scorsese | F24: 8.7 | G24: 8 | H24: 1406721 | I24: EE.UU. | J24: Drama | K24: Crimen | L24: Movistar, Movistar Plus+ Ficción Total , HBO Max, HBO Max Amazon Channel | M24: El ascenso y caída de un gánster de barrio. | N24: 1 | O24: 0 | P24: 0 | Q24: 6 | R24: 0 | S24: 0 | T24: 63 | U24: =O24*4 + P24*2 + MAX(0,N24-O24-P24)*1 + Q24*0.2 + R24*2 + S24*1 + IF(T24="",0,IF(T24<=10,8,IF(T24<=50,6,IF(T24<=100,4,2)))) -> 6.2 | V24: Uno de los nuestros (1990) redefinió el cine de mafia moderno con su voz en off, montaje vertiginoso y uso de. | W24: TOP 20-30 | Y24: tt0099685
A25: El apartamento | B25: 1960 | C25: 1960s | D25: 125 | E25: Billy Wilder | F25: 8.3 | H25: 222306 | I25: EE.UU. | J25: Romance | K25: Comedia | L25: MGM Plus Amazon Channel | M25: Un oficinista presta su piso a los jefes para sus líos. | N25: 5 | O25: 1 | P25: 1 | Q25: 10 | R25: 0 | S25: 1 | T25: 54 | U25: =O25*4 + P25*2 + MAX(0,N25-O25-P25)*1 + Q25*0.2 + R25*2 + S25*1 + IF(T25="",0,IF(T25<=10,8,IF(T25<=50,6,IF(T25<=100,4,2)))) -> 16 | V25: El apartamento (1960) es considerada una obra clave del género comedia, romance, y una pieza importante en la. | W25: TOP 30-40 | Y25: tt0053604
A26: Indiana Jones y el templo maldito | B26: 1984 | C26: 1980s | D26: 118 | E26: Steven Spielberg | F26: 7.5 | H26: 572243 | I26: EE.UU. | J26: Acción | K26: Aventura | L26: Movistar Plus+ Ficción Total , SkyShowtime | M26: 1935. | N26: 1 | O26: 0 | P26: 0 | Q26: 2 | R26: 0 | S26: 0 | U26: =O26*4 + P26*2 + MAX(0,N26-O26-P26)*1 + Q26*0.2 + R26*2 + S26*1 + IF(T26="",0,IF(T26<=10,8,IF(T26<=50,6,IF(T26<=100,4,2)))) -> 1.4 | Y26: tt0087469
A27: Los siete samuráis | B27: 1954 | C27: 1950s | D27: 207 | E27: Akira Kurosawa | F27: 8.6 | G27: 8 | H27: 406042 | I27: Japón | J27: Acción | K27: Drama | L27: Movistar, Movistar Plus+ Ficción Total , Filmin, Acontra, Acontra Plus Amazon Channel, Tivify, Runtime | M27: Unos aldeanos contratan samuráis para defenderse de bandidos. | N27: 0 | O27: 0 | P27: 0 | Q27: 2 | R27: 0 | S27: 0 | T27: 20 | U27: =O27*4 + P27*2 + MAX(0,N27-O27-P27)*1 + Q27*0.2 + R27*2 + S27*1 + IF(T27="",0,IF(T27<=10,8,IF(T27<=50,6,IF(T27<=100,4,2)))) -> 6.4 | V27: Los siete samuráis (1954) es pilar del cine de aventuras y acción en grupo; su estructura ha sido imitada en. | W27: TOP 10-20 | Y27: tt0047478
A28: Alguien voló sobre el nido del cuco | B28: 1975 | C28: 1970s | D28: 133 | E28: Milos Forman | F28: 8.6 | G28: 7 | H28: 1163711 | I28: EE.UU. | J28: Drama | L28: Filmin | M28: Un rebelde preso es enviado a un hospital psiquiátrico dominado por una enfermera tiránica. | N28: 5 | O28: 1 | P28: 1 | Q28: 9 | R28: 0 | S28: 1 | U28: =O28*4 + P28*2 + MAX(0,N28-O28-P28)*1 + Q28*0.2 + R28*2 + S28*1 + IF(T28="",0,IF(T28<=10,8,IF(T28<=50,6,IF(T28<=100,4,2)))) -> 11.8 | V28: Alguien voló sobre el nido del cuco (1975) es símbolo de la rebelión contra las instituciones opresivas y. | Y28: tt0073486
A29: La milla verde | B29: 1999 | C29: 1990s | D29: 189 | E29: Frank Darabont | F29: 8.6 | H29: 1578084 | I29: EE.UU. | J29: Fantasía | K29: Crimen | L29: Movistar, Movistar Plus+ Ficción Total | M29: Un guardia de prisiones descubre que un condenado a muerte posee un don sobrenatural capaz de. | N29: 0 | O29: 0 | P29: 0 | Q29: 4 | R29: 0 | S29: 0 | U29: =O29*4 + P29*2 + MAX(0,N29-O29-P29)*1 + Q29*0.2 + R29*2 + S29*1 + IF(T29="",0,IF(T29<=10,8,IF(T29<=50,6,IF(T29<=100,4,2)))) -> 0.8 | Y29: tt0120689
A30: Apocalypse Now | B30: 1979 | C30: 1970s | D30: 147 | E30: Francis F. Coppola | F30: 8.4 | H30: 775671 | I30: EE.UU. | J30: Bélico | K30: Misterio | L30: Filmin | M30: Un capitán remonta el río para eliminar a un coronel renegado. | N30: 2 | O30: 0 | P30: 0 | Q30: 8 | R30: 1 | S30: 0 | T30: 19 | U30: =O30*4 + P30*2 + MAX(0,N30-O30-P30)*1 + Q30*0.2 + R30*2 + S30*1 + IF(T30="",0,IF(T30<=10,8,IF(T30<=50,6,IF(T30<=100,4,2)))) -> 11.6 | V30: Apocalypse Now (1979) es considerada una obra clave del género bélico, drama, y una pieza importante en la. | W30: TOP 10-20 | Y30: tt0078788
A31: La evasión | B31: 1960 | C31: 1960s | D31: 131 | E31: Jacques Becker | F31: 8.5 | H31: 24017 | I31: Francia | J31: Thriller | K31: Crimen | L31: Tivify | M31: Un preso político trama una fuga minuciosa durante la Segunda Guerra Mundial. | N31: 0 | O31: 0 | P31: 0 | Q31: 0 | R31: 0 | S31: 0 | U31: =O31*4 + P31*2 + MAX(0,N31-O31-P31)*1 + Q31*0.2 + R31*2 + S31*1 + IF(T31="",0,IF(T31<=10,8,IF(T31<=50,6,IF(T31<=100,4,2)))) -> 0 | V31: La evasión (1960) es considerada una obra clave del género crimen, thriller, prisión, y una pieza importante. | Y31: tt0054407
A32: Seven | B32: 1995 | C32: 1990s | D32: 127 | E32: David Fincher | F32: 8.6 | G32: 9 | H32: 2048370 | I32: EE.UU. | J32: Drama | K32: Crimen | L32: Prime, Movistar Plus+ Ficción Total | M32: Dos detectives persiguen a un asesino serial que usa los siete pecados capitales. | N32: 0 | O32: 0 | P32: 0 | Q32: 1 | R32: 0 | S32: 0 | U32: =O32*4 + P32*2 + MAX(0,N32-O32-P32)*1 + Q32*0.2 + R32*2 + S32*1 + IF(T32="",0,IF(T32<=10,8,IF(T32<=50,6,IF(T32<=100,4,2)))) -> 0.2 | V32: Seven (1995) redefinió el thriller oscuro contemporáneo, con un final impactante y una atmósfera opresiva muy. | Y32: tt0114369
A33: Mar adentro | B33: 2004 | C33: 2000s | D33: 126 | E33: Alejandro Amenábar | F33: 7.9 | H33: 89284 | I33: España | J33: Drama | K33: Biográfico | L33: Netflix, Movistar Plus+ Ficción Total , FlixOlé, HBO Max, FlixOlé Amazon Channel, HBO Max Amazon Channel | M33: Ramón (Javier Bardem) lleva casi treinta años postrado en una cama al cuidado de su familia. | N33: 1 | O33: 0 | P33: 0 | Q33: 2 | R33: 0 | S33: 0 | U33: =O33*4 + P33*2 + MAX(0,N33-O33-P33)*1 + Q33*0.2 + R33*2 + S33*1 + IF(T33="",0,IF(T33<=10,8,IF(T33<=50,6,IF(T33<=100,4,2)))) -> 1.4 | Y33: tt0369702
A34: El golpe | B34: 1973 | C34: 1970s | D34: 129 | E34: George Roy Hill | F34: 8.2 | H34: 304623 | I34: EE.UU. | J34: Comedia | K34: Crimen | L34: Netflix | M34: Dos estafadores planean un gran golpe en los años 30. | N34: 7 | O34: 1 | P34: 1 | Q34: 10 | R34: 0 | S34: 0 | U34: =O34*4 + P34*2 + MAX(0,N34-O34-P34)*1 + Q34*0.2 + R34*2 + S34*1 + IF(T34="",0,IF(T34<=10,8,IF(T34<=50,6,IF(T34<=100,4,2)))) -> 13 | V34: El golpe (1973) consolidó el cine de estafas como gran espectáculo popular, con un guion modélico lleno de. | Y34: tt0070735
A35: Casablanca | B35: 1942 | C35: 1940s | D35: 102 | E35: Michael Curtiz | F35: 8.5 | H35: 659159 | I35: EE.UU. | J35: Bélico | K35: Espionaje | M35: Un hombre debe elegir entre su amor y ayudar a la resistencia durante la Segunda Guerra. | N35: 3 | O35: 1 | P35: 1 | Q35: 8 | R35: 0 | S35: 0 | T35: 63 | U35: =O35*4 + P35*2 + MAX(0,N35-O35-P35)*1 + Q35*0.2 + R35*2 + S35*1 + IF(T35="",0,IF(T35<=10,8,IF(T35<=50,6,IF(T35<=100,4,2)))) -> 12.6 | V35: Casablanca (1942) es un melodrama romántico icónico, estudiado por su guion, diálogos y uso del contexto. | Y35: tt0034583
A36: Cinema Paradiso | B36: 1988 | C36: 1980s | D36: 174 | E36: Giuseppe Tornatore | F36: 8.5 | H36: 319465 | I36: Italia | J36: Romance | K36: Coming of age | L36: Prime, Acontra | M36: Un cineasta recuerda su infancia marcada por su amistad con el proyeccionista del cine local. | N36: 1 | O36: 0 | P36: 0 | Q36: 1 | R36: 0 | S36: 0 | U36: =O36*4 + P36*2 + MAX(0,N36-O36-P36)*1 + Q36*0.2 + R36*2 + S36*1 + IF(T36="",0,IF(T36<=10,8,IF(T36<=50,6,IF(T36<=100,4,2)))) -> 1.2 | V36: Cinema Paradiso (1988) es quizá la carta de amor al cine más famosa, consolidando la idea del cine como. | Y36: tt0095765
A37: La historia interminable | B37: 1984 | C37: 1980s | D37: 102 | E37: Wolfgang Petersen | F37: 7.3 | H37: 171979 | I37: Alemania | J37: Aventura | K37: Familiar | L37: Lionsgate+ Amazon Channel, Rakuten | M37: Un niño viaja a un mundo mágico para salvar a la Emperatriz Infantil y detener la Nada que. | N37: 0 | O37: 0 | P37: 0 | Q37: 0 | R37: 0 | S37: 0 | U37: =O37*4 + P37*2 + MAX(0,N37-O37-P37)*1 + Q37*0.2 + R37*2 + S37*1 + IF(T37="",0,IF(T37<=10,8,IF(T37<=50,6,IF(T37<=100,4,2)))) -> 0 | Y37: tt0088323
A38: Con faldas y a lo loco | B38: 1959 | C38: 1950s | D38: 121 | E38: Billy Wilder | F38: 8.2 | H38: 306558 | I38: EE.UU. | J38: Musical | K38: Romance | L38: MGM Plus Amazon Channel | M38: Dos músicos huyen disfrazados de mujer tras presenciar un crimen. | N38: 1 | O38: 0 | P38: 0 | Q38: 6 | R38: 0 | S38: 1 | T38: 38 | U38: =O38*4 + P38*2 + MAX(0,N38-O38-P38)*1 + Q38*0.2 + R38*2 + S38*1 + IF(T38="",0,IF(T38<=10,8,IF(T38<=50,6,IF(T38<=100,4,2)))) -> 9.2 | V38: Con faldas y a lo loco (1959) es considerada una obra clave del género comedia, y una pieza importante en la. | Y38: tt0053291
A39: Sin perdón | B39: 1992 | C39: 1990s | D39: 130 | E39: Clint Eastwood | F39: 8.2 | G39: 8 | H39: 471361 | I39: EE.UU. | J39: Western | K39: Drama | L39: Movistar, Movistar Plus+ Ficción Total | M39: Un pistolero retirado acepta un último encargo. | N39: 4 | O39: 1 | P39: 1 | Q39: 9 | R39: 0 | S39: 0 | U39: =O39*4 + P39*2 + MAX(0,N39-O39-P39)*1 + Q39*0.2 + R39*2 + S39*1 + IF(T39="",0,IF(T39<=10,8,IF(T39<=50,6,IF(T39<=100,4,2)))) -> 9.8 | V39: Sin perdón (1992) es considerada una obra clave del género western, drama, y una pieza importante en la. | W39: TOP 30-40 | Y39: tt0105695
A40: El precio del poder | B40: 1983 | C40: 1980s | D40: 170 | E40: Brian De Palma | F40: 8.3 | G40: 9 | H40: 1029271 | I40: EE.UU. | J40: Drama | K40: Crimen | L40: Netflix, rtve | M40: Tony Montana asciende en el narcotráfico hasta caer víctima de su ambición. | N40: 0 | O40: 0 | P40: 0 | Q40: 0 | R40: 0 | S40: 0 | U40: =O40*4 + P40*2 + MAX(0,N40-O40-P40)*1 + Q40*0.2 + R40*2 + S40*1 + IF(T40="",0,IF(T40<=10,8,IF(T40<=50,6,IF(T40<=100,4,2)))) -> 0 | V40: El precio del poder (1983) es considerada una obra clave del género crimen, y una pieza importante en la. | Y40: tt0086250
...

Sheet Series
A1: Serie | B1: Año inicio | C1: Año fin | D1: Década | E1: Tipo | F1: Creador | G1: IMDb | H1: Mi nota | I1: Votos | J1: País | K1: Género | L1: Subgénero | M1: VOD (04/10/2026) | N1: Sinopsis | O1: Emmys | P1: Emmy Serie | Q1: Nom. Emmy | R1: Importancia histórica | S1: IMDb ID
A2: Breaking Bad | B2: 2008 | C2: 2013 | D2: 2000s | E2: Serie | F2: Michelle MacLaren, Adam Bernstein | G2: 9.5 | H2: 9 | I2: 2659109 | K2: Thriller | L2: Crimen | M2: Netflix | O2: 24 | P2: 1 | Q2: 114 | S2: tt0903747
A3: Juego de tronos | B3: 2011 | C3: 2019 | D3: 2010s | E3: Serie | F3: David Nutter, Alan Taylor | G3: 9.2 | H3: 10 | I3: 2648630 | K3: Fantasía | L3: Drama | M3: Movistar Plus+ Ficción Total , HBO Max | O3: 245 | P3: 1 | Q3: 466 | S3: tt0944947
A4: Stranger Things | B4: 2016 | C4: 2025 | D4: 2010s | E4: Serie | F4: Matt Duffer, Ross Duffer | G4: 8.6 | H4: 8 | I4: 1728260 | K4: Terror | L4: Fantasía | M4: Netflix | O4: 36 | P4: 0 | Q4: 113 | S4: tt4574334
A5: The Walking Dead | B5: 2010 | C5: 2022 | D5: 2010s | E5: Serie | F5: Greg Nicotero, Michael E. Satrazemis | G5: 8.1 | H5: 8 | I5: 1208602 | K5: Terror | L5: Thriller | M5: Netflix, Prime, Disney+, Movistar Plus+ Ficción Total , AMC+ Amazon Channel, AMC Plus Apple TV channel | O5: 14 | P5: 0 | Q5: 101 | S5: tt1520211
A6: Friends | B6: 1994 | C6: 2004 | D6: 1990s | E6: Serie | F6: Gary Halvorson, Kevin Bright | G6: 8.8 | I6: 1202980 | K6: Romance | L6: Comedia | M6: Netflix, Movistar Plus+ Ficción Total , HBO Max, Tivify, HBO Max Amazon Channel | O6: 2 | P6: 0 | Q6: 20 | S6: tt0108778
A7: Sherlock | B7: 2010 | C7: 2017 | D7: 2010s | E7: Serie | F7: Paul McGuigan, Jeremy Lovering | G7: 9 | H7: 7 | I7: 1096466 | K7: Drama | L7: Crimen | M7: Disney+ | O7: 14 | P7: 0 | Q7: 69 | S7: tt1475582
A8: Chernobyl | B8: 2019 | C8: 2019 | D8: 2010s | E8: Miniserie | F8: Johan Renck | G8: 9.3 | H8: 8 | I8: 1056716 | K8: Thriller | L8: Histórico | M8: Movistar Plus+ Ficción Total , HBO Max, HBO Max Amazon Channel | O8: 32 | P8: 1 | Q8: 49 | S8: tt7366338
A9: The Boys | B9: 2019 | C9: 2026 | D9: 2010s | E9: Serie | F9: Philip Sgriccia, Karen Gaviola | G9: 8.5 | H9: 9 | I9: 1017599 | K9: Acción | L9: Crimen | M9: Prime | O9: 0 | P9: 0 | Q9: 41 | S9: tt1190634
A10: Dexter | B10: 2006 | C10: 2013 | D10: 2000s | E10: Serie | F10: John Dahl, Steve Shill | G10: 8.6 | I10: 949478 | K10: Drama | L10: Crimen | M10: Netflix, Movistar Plus+ Ficción Total , SkyShowtime | O10: 7 | P10: 0 | Q10: 68 | S10: tt0773262
A11: Big Bang | B11: 2007 | C11: 2019 | D11: 2000s | E11: Serie | F11: Mark Cendrowski, Anthony Rich | G11: 8.1 | I11: 943333 | K11: Romance | L11: Comedia | M11: Movistar Plus+ Ficción Total , HBO Max, Tivify, HBO Max Amazon Channel | O11: 13 | P11: 0 | Q11: 130 | S11: tt0898266
A12: Better Call Saul | B12: 2015 | C12: 2022 | D12: 2010s | E12: Serie | F12: Vince Gilligan, Thomas Schnauz | G12: 9 | H12: 9 | I12: 855649 | K12: Drama | L12: Crimen | M12: Netflix | O12: 0 | P12: 0 | Q12: 122 | S12: tt3032476
A13: The Office | B13: 2005 | C13: 2013 | D13: 2000s | E13: Serie | F13: Paul Feig, Randall Einhorn | G13: 9 | H13: 10 | I13: 844701 | K13: Comedia | M13: Netflix, Prime, Disney+, Movistar Plus+ Ficción Total , SkyShowtime | O13: 6 | P13: 0 | Q13: 135 | S13: tt0386676
A14: Peaky Blinders | B14: 2013 | C14: 2022 | D14: 2010s | E14: Serie | F14: Anthony Byrne, Colm McCarthy | G14: 8.7 | H14: 9 | I14: 788117 | K14: Drama | L14: Crimen | M14: Netflix, Prime | O14: 0 | P14: 0 | Q14: 0 | S14: tt2442560
A15: Cómo conocí a vuestra madre | B15: 2005 | C15: 2014 | D15: 2000s | E15: Serie | F15: Pamela Fryman, Rob Greenberg | G15: 8.3 | H15: 8 | I15: 787329 | K15: Romance | L15: Comedia | M15: Disney+ | O15: 10 | P15: 0 | Q15: 53 | S15: tt0460649
A16: El juego del calamar | B16: 2021 | C16: 2025 | D16: 2020s | E16: Serie | F16: Hwang Dong-hyuk | G16: 7.9 | H16: 8 | I16: 772350 | K16: Acción | L16: Crimen | M16: Netflix | O16: 0 | P16: 0 | Q16: 0 | S16: tt10919420
A17: True Detective: Noche polar | B17: 2014 | D17: 2010s | E17: Serie | F17: Cary Joji Fukunaga, Issa López | G17: 8.8 | I17: 765168 | K17: Drama | L17: Crimen | M17: Movistar Plus+ Ficción Total , HBO Max, HBO Max Amazon Channel | O17: 0 | P17: 0 | Q17: 37 | S17: tt2356777
A18: Los últimos de nosotros | B18: 2023 | D18: 2020s | E18: Serie | F18: Craig Mazin, Neil Druckmann | G18: 8.4 | H18: 8 | I18: 746592 | K18: Acción | L18: Aventura | O18: 0 | P18: 0 | Q18: 0
A19: Black Mirror | B19: 2011 | D19: 2010s | E19: Serie | F19: Toby Haynes, Owen Harris | G19: 8.7 | H19: 9 | I19: 745407 | K19: Drama | L19: Crimen | M19: Netflix | O19: 0 | P19: 0 | Q19: 1 | S19: tt2085059
A20: Ataque a los titanes | B20: 2013 | C20: 2023 | D20: 2010s | E20: Serie | F20: Tetsurō Araki, Masashi Koizuka | G20: 9.1 | I20: 737873 | K20: Animación | L20: Acción | M20: Netflix, Prime, Crunchyroll, Crunchyroll Amazon Channel, Animebox Channel Amazon Channel | O20: 0 | P20: 0 | Q20: 0 | S20: tt2560140
A21: Rick y Morty | B21: 2013 | D21: 2010s | E21: Serie | F21: Wes Archer, Jacob Hair | G21: 9 | I21: 707560 | K21: Animación | L21: Aventura | M21: Netflix, Movistar Plus+ Ficción Total , HBO Max, HBO Max Amazon Channel | O21: 37 | P21: 0 | Q21: 41 | S21: tt2861424
A22: Perdidos | B22: 2004 | C22: 2010 | D22: 2000s | E22: Serie | F22: Jack Bender, Stephen Williams | G22: 8.3 | H22: 9 | I22: 679064 | K22: Fantasía | L22: Aventura | M22: Disney+ | O22: 9 | P22: 0 | Q22: 127 | S22: tt0411008
A23: Prison Break | B23: 2005 | C23: 2017 | D23: 2000s | E23: Serie | F23: Bobby Roth, Kevin Hooks | G23: 8.3 | I23: 676791 | K23: Acción | L23: Crimen | M23: Disney+ | O23: 0 | P23: 0 | Q23: 0 | S23: tt0455275
A24: Gambito de dama | B24: 2020 | C24: 2020 | D24: 2020s | E24: Miniserie | F24: Scott Frank | G24: 8.5 | H24: 6 | I24: 674068 | K24: Drama | M24: Netflix | O24: 34 | P24: 0 | Q24: 44 | S24: tt10048342
A25: The Mandalorian | B25: 2019 | C25: 2023 | D25: 2010s | E25: Serie | F25: Rick Famuyiwa, Bryce Dallas Howard | G25: 8.6 | H25: 10 | I25: 663211 | K25: Fantasía | L25: Acción | M25: Disney+ | O25: 54 | P25: 0 | Q25: 116 | S25: tt8111088
A26: Vikingos | B26: 2013 | C26: 2020 | D26: 2010s | E26: Serie | F26: Ciaran Donnelly, Ken Girotti | G26: 8.5 | H26: 8 | I26: 647472 | K26: Acción | L26: Aventura | M26: Netflix | O26: 9 | P26: 0 | Q26: 93 | S26: tt2306299
A27: The Witcher | B27: 2019 | D27: 2010s | E27: Serie | F27: Alex Garcia Lopez, Jeremy Webb | G27: 7.8 | H27: 7 | I27: 623459 | K27: Acción | L27: Aventura | M27: Netflix | O27: 0 | P27: 0 | Q27: 0 | S27: tt5180504
A28: La casa de papel | B28: 2017 | C28: 2021 | D28: 2010s | E28: Serie | F28: Jesús Colmenar, Alex Rodrigo | G28: 8.2 | I28: 615958 | K28: Acción | L28: Crimen | M28: Netflix, atresplayer | O28: 0 | P28: 0 | Q28: 0 | S28: tt6468322
A29: Hermanos de sangre | B29: 2001 | C29: 2001 | D29: 2000s | E29: Miniserie | F29: David Frankel, Mikael Salomon | G29: 9.4 | H29: 10 | I29: 601272 | K29: Acción | L29: Histórico | M29: Prime, HBO Max, HBO Max Amazon Channel | O29: 0 | P29: 0 | Q29: 0 | S29: tt0185906
A30: House | B30: 2004 | C30: 2012 | D30: 2000s | E30: Serie | F30: Greg Yaitanes, Deran Sarafian | G30: 8.7 | I30: 598198 | K30: Drama | M30: Netflix, Movistar Plus+ Ficción Total , SkyShowtime | O30: 11 | P30: 0 | Q30: 82 | S30: tt0412142
A31: Los Soprano | B31: 1999 | C31: 2007 | D31: 1990s | E31: Serie | F31: Timothy Van Patten, John Patterson | G31: 9.2 | I31: 591163 | K31: Drama | L31: Crimen | M31: Movistar Plus+ Ficción Total , HBO Max, HBO Max Amazon Channel | O31: 25 | P31: 1 | Q31: 47 | S31: tt0141842
A32: House of Cards | B32: 2013 | C32: 2018 | D32: 2010s | E32: Serie | F32: James Foley, Robin Wright | G32: 8.6 | H32: 9 | I32: 562047 | K32: Thriller | L32: Drama | M32: Netflix | O32: 7 | P32: 0 | Q32: 119 | S32: tt1856010
A33: La casa del dragón | B33: 2022 | D33: 2020s | E33: Serie | F33: Clare Kilner, Geeta Vasant Patel | G33: 8.3 | H33: 8 | I33: 560835 | K33: Acción | L33: Aventura | M33: Movistar Plus+ Ficción Total , HBO Max, HBO Max Amazon Channel | O33: 0 | P33: 0 | Q33: 0 | S33: tt11198330
A34: Westworld | B34: 2016 | C34: 2022 | D34: 2010s | E34: Serie | F34: Richard J. Lewis, Jonathan Nolan | G34: 8.4 | I34: 560086 | K34: Ciencia ficción | L34: Misterio | O34: 41 | P34: 0 | Q34: 207 | S34: tt0475784
A35: Dark | B35: 2017 | C35: 2020 | D35: 2010s | E35: Serie | F35: Baran bo Odar | G35: 8.7 | I35: 557436 | K35: Drama | L35: Crimen | M35: Netflix | O35: 0 | P35: 0 | Q35: 0 | S35: tt5753856
A36: Suits: La clave del éxito | B36: 2011 | C36: 2019 | D36: 2010s | E36: Serie | F36: Michael Smith, Anton Cropper | G36: 8.4 | I36: 546718 | K36: Comedia | L36: Drama | M36: Netflix, Prime, Movistar Plus+ Ficción Total , SkyShowtime | O36: 0 | P36: 0 | Q36: 0 | S36: tt1632701
A37: Sobrenatural | B37: 2005 | C37: 2020 | D37: 2000s | E37: Serie | F37: Robert Singer, Philip Sgriccia | G37: 8.4 | I37: 545519 | K37: Terror | L37: Fantasía | M37: Prime, Movistar Plus+ Ficción Total , HBO Max, HBO Max Amazon Channel | O37: 0 | P37: 0 | Q37: 10 | S37: tt0460681
A38: Modern Family | B38: 2009 | C38: 2020 | D38: 2000s | E38: Serie | F38: Gail Mancuso, Steven Levitan | G38: 8.5 | H38: 8 | I38: 545098 | K38: Romance | L38: Comedia | M38: Disney+ | O38: 71 | P38: 1 | Q38: 162 | S38: tt1442437
A39: Daredevil | B39: 2015 | C39: 2018 | D39: 2010s | E39: Serie | F39: Phil Abraham, Stephen Surjik | G39: 8.6 | I39: 538914 | K39: Acción | L39: Crimen | M39: Disney+ | O39: 0 | P39: 0 | Q39: 0 | S39: tt3322312
A40: Narcos | B40: 2015 | C40: 2017 | D40: 2010s | E40: Serie | F40: Andrés Baiz, Josef Kubota Wladyka | G40: 8.7 | H40: 8 | I40: 533791 | K40: Drama | L40: Crimen | M40: Netflix | O40: 0 | P40: 0 | Q40: 6 | S40: tt2707408
...

Sheet Análisis
A1: RESUMEN
A2: Películas en la lista | B2: =COUNTA('Movie Data Base by Keizar'!A2:A4000) -> 2382
A3: Vistas (con tu nota) | B3: =COUNT('Movie Data Base by Keizar'!G2:G4000) -> 1285
A4: Tu nota media | B4: =ROUND(AVERAGE('Movie Data Base by Keizar'!G2:G4000),2) -> 6.26
A5: Nota media IMDb (vistas) | B5: =ROUND(AVERAGEIF('Movie Data Base by Keizar'!G2:G4000,">0",'Movie Data Base by Keizar'!F2:F4000),2) -> 6.9
A6: Horas vistas (aprox.) | B6: =ROUND(SUMIF('Movie Data Base by Keizar'!G2:G4000,">0",'Movie Data Base by Keizar'!D2:D4000)/60,0) -> 2457
A7: Duración media (min) | B7: =ROUND(AVERAGE('Movie Data Base by Keizar'!D2:D4000),0) -> 117
A10: POR GÉNERO | F10: POR DÉCADA | K10: TUS NOTAS
A11: Género | B11: En lista | C11: Vistas | D11: Tu media | F11: Década | G11: En lista | H11: Vistas | I11: Tu media | K11: Nota | L11: Nº pelis
A12: Drama | B12: =COUNTIF('Movie Data Base by Keizar'!J:J,A12) -> 428 | C12: =COUNTIFS('Movie Data Base by Keizar'!J:J,A12,'Movie Data Base by Keizar'!G:G,">0") -> 117 | D12: =IFERROR(ROUND(AVERAGEIFS('Movie Data Base by Keizar'!G:G,'Movie Data Base by Keizar'!J:J,A12,'Movie Data Base by Keizar'!G:G,">0"),2),"") -> 6.93 | F12: 1920s | G12: =COUNTIF('Movie Data Base by Keizar'!C:C,F12) -> 15 | H12: =COUNTIFS('Movie Data Base by Keizar'!C:C,F12,'Movie Data Base by Keizar'!G:G,">0") -> 1 | I12: =IFERROR(ROUND(AVERAGEIFS('Movie Data Base by Keizar'!G:G,'Movie Data Base by Keizar'!C:C,F12,'Movie Data Base by Keizar'!G:G,">0"),2),"") -> 6 | K12: 10 | L12: =COUNTIF('Movie Data Base by Keizar'!G:G,K12) -> 7
A13: Thriller | B13: =COUNTIF('Movie Data Base by Keizar'!J:J,A13) -> 279 | C13: =COUNTIFS('Movie Data Base by Keizar'!J:J,A13,'Movie Data Base by Keizar'!G:G,">0") -> 194 | D13: =IFERROR(ROUND(AVERAGEIFS('Movie Data Base by Keizar'!G:G,'Movie Data Base by Keizar'!J:J,A13,'Movie Data Base by Keizar'!G:G,">0"),2),"") -> 6.43 | F13: 1930s | G13: =COUNTIF('Movie Data Base by Keizar'!C:C,F13) -> 17 | H13: =COUNTIFS('Movie Data Base by Keizar'!C:C,F13,'Movie Data Base by Keizar'!G:G,">0") -> 0 | I13: =IFERROR(ROUND(AVERAGEIFS('Movie Data Base by Keizar'!G:G,'Movie Data Base by Keizar'!C:C,F13,'Movie Data Base by Keizar'!G:G,">0"),2),"") | K13: 9 | L13: =COUNTIF('Movie Data Base by Keizar'!G:G,K13) -> 56
A14: Romance | B14: =COUNTIF('Movie Data Base by Keizar'!J:J,A14) -> 236 | C14: =COUNTIFS('Movie Data Base by Keizar'!J:J,A14,'Movie Data Base by Keizar'!G:G,">0") -> 68 | D14: =IFERROR(ROUND(AVERAGEIFS('Movie Data Base by Keizar'!G:G,'Movie Data Base by Keizar'!J:J,A14,'Movie Data Base by Keizar'!G:G,">0"),2),"") -> 5.96 | F14: 1940s | G14: =COUNTIF('Movie Data Base by Keizar'!C:C,F14) -> 31 | H14: =COUNTIFS('Movie Data Base by Keizar'!C:C,F14,'Movie Data Base by Keizar'!G:G,">0") -> 1 | I14: =IFERROR(ROUND(AVERAGEIFS('Movie Data Base by Keizar'!G:G,'Movie Data Base by Keizar'!C:C,F14,'Movie Data Base by Keizar'!G:G,">0"),2),"") -> 7 | K14: 8 | L14: =COUNTIF('Movie Data Base by Keizar'!G:G,K14) -> 196
A15: Acción | B15: =COUNTIF('Movie Data Base by Keizar'!J:J,A15) -> 214 | C15: =COUNTIFS('Movie Data Base by Keizar'!J:J,A15,'Movie Data Base by Keizar'!G:G,">0") -> 182 | D15: =IFERROR(ROUND(AVERAGEIFS('Movie Data Base by Keizar'!G:G,'Movie Data Base by Keizar'!J:J,A15,'Movie Data Base by Keizar'!G:G,">0"),2),"") -> 5.97 | F15: 1950s | G15: =COUNTIF('Movie Data Base by Keizar'!C:C,F15) -> 44 | H15: =COUNTIFS('Movie Data Base by Keizar'!C:C,F15,'Movie Data Base by Keizar'!G:G,">0") -> 3 | I15: =IFERROR(ROUND(AVERAGEIFS('Movie Data Base by Keizar'!G:G,'Movie Data Base by Keizar'!C:C,F15,'Movie Data Base by Keizar'!G:G,">0"),2),"") -> 7.33 | K15: 7 | L15: =COUNTIF('Movie Data Base by Keizar'!G:G,K15) -> 333
A16: Terror | B16: =COUNTIF('Movie Data Base by Keizar'!J:J,A16) -> 203 | C16: =COUNTIFS('Movie Data Base by Keizar'!J:J,A16,'Movie Data Base by Keizar'!G:G,">0") -> 176 | D16: =IFERROR(ROUND(AVERAGEIFS('Movie Data Base by Keizar'!G:G,'Movie Data Base by Keizar'!J:J,A16,'Movie Data Base by Keizar'!G:G,">0"),2),"") -> 5.89 | F16: 1960s | G16: =COUNTIF('Movie Data Base by Keizar'!C:C,F16) -> 57 | H16: =COUNTIFS('Movie Data Base by Keizar'!C:C,F16,'Movie Data Base by Keizar'!G:G,">0") -> 6 | I16: =IFERROR(ROUND(AVERAGEIFS('Movie Data Base by Keizar'!G:G,'Movie Data Base by Keizar'!C:C,F16,'Movie Data Base by Keizar'!G:G,">0"),2),"") -> 7 | K16: 6 | L16: =COUNTIF('Movie Data Base by Keizar'!G:G,K16) -> 362
A17: Comedia | B17: =COUNTIF('Movie Data Base by Keizar'!J:J,A17) -> 199 | C17: =COUNTIFS('Movie Data Base by Keizar'!J:J,A17,'Movie Data Base by Keizar'!G:G,">0") -> 101 | D17: =IFERROR(ROUND(AVERAGEIFS('Movie Data Base by Keizar'!G:G,'Movie Data Base by Keizar'!J:J,A17,'Movie Data Base by Keizar'!G:G,">0"),2),"") -> 6.28 | F17: 1970s | G17: =COUNTIF('Movie Data Base by Keizar'!C:C,F17) -> 82 | H17: =COUNTIFS('Movie Data Base by Keizar'!C:C,F17,'Movie Data Base by Keizar'!G:G,">0") -> 21 | I17: =IFERROR(ROUND(AVERAGEIFS('Movie Data Base by Keizar'!G:G,'Movie Data Base by Keizar'!C:C,F17,'Movie Data Base by Keizar'!G:G,">0"),2),"") -> 7.52 | K17: 5 | L17: =COUNTIF('Movie Data Base by Keizar'!G:G,K17) -> 172
A18: Animación | B18: =COUNTIF('Movie Data Base by Keizar'!J:J,A18) -> 182 | C18: =COUNTIFS('Movie Data Base by Keizar'!J:J,A18,'Movie Data Base by Keizar'!G:G,">0") -> 92 | D18: =IFERROR(ROUND(AVERAGEIFS('Movie Data Base by Keizar'!G:G,'Movie Data Base by Keizar'!J:J,A18,'Movie Data Base by Keizar'!G:G,">0"),2),"") -> 6.24 | F18: 1980s | G18: =COUNTIF('Movie Data Base by Keizar'!C:C,F18) -> 130 | H18: =COUNTIFS('Movie Data Base by Keizar'!C:C,F18,'Movie Data Base by Keizar'!G:G,">0") -> 40 | I18: =IFERROR(ROUND(AVERAGEIFS('Movie Data Base by Keizar'!G:G,'Movie Data Base by Keizar'!C:C,F18,'Movie Data Base by Keizar'!G:G,">0"),2),"") -> 6.55 | K18: 4 | L18: =COUNTIF('Movie Data Base by Keizar'!G:G,K18) -> 85
A19: Ciencia ficción | B19: =COUNTIF('Movie Data Base by Keizar'!J:J,A19) -> 161 | C19: =COUNTIFS('Movie Data Base by Keizar'!J:J,A19,'Movie Data Base by Keizar'!G:G,">0") -> 144 | D19: =IFERROR(ROUND(AVERAGEIFS('Movie Data Base by Keizar'!G:G,'Movie Data Base by Keizar'!J:J,A19,'Movie Data Base by Keizar'!G:G,">0"),2),"") -> 6.25 | F19: 1990s | G19: =COUNTIF('Movie Data Base by Keizar'!C:C,F19) -> 263 | H19: =COUNTIFS('Movie Data Base by Keizar'!C:C,F19,'Movie Data Base by Keizar'!G:G,">0") -> 134 | I19: =IFERROR(ROUND(AVERAGEIFS('Movie Data Base by Keizar'!G:G,'Movie Data Base by Keizar'!C:C,F19,'Movie Data Base by Keizar'!G:G,">0"),2),"") -> 6.93 | K19: 3 | L19: =COUNTIF('Movie Data Base by Keizar'!G:G,K19) -> 53
A20: Fantasía | B20: =COUNTIF('Movie Data Base by Keizar'!J:J,A20) -> 140 | C20: =COUNTIFS('Movie Data Base by Keizar'!J:J,A20,'Movie Data Base by Keizar'!G:G,">0") -> 100 | D20: =IFERROR(ROUND(AVERAGEIFS('Movie Data Base by Keizar'!G:G,'Movie Data Base by Keizar'!J:J,A20,'Movie Data Base by Keizar'!G:G,">0"),2),"") -> 6.19 | F20: 2000s | G20: =COUNTIF('Movie Data Base by Keizar'!C:C,F20) -> 744 | H20: =COUNTIFS('Movie Data Base by Keizar'!C:C,F20,'Movie Data Base by Keizar'!G:G,">0") -> 434 | I20: =IFERROR(ROUND(AVERAGEIFS('Movie Data Base by Keizar'!G:G,'Movie Data Base by Keizar'!C:C,F20,'Movie Data Base by Keizar'!G:G,">0"),2),"") -> 6.38 | K20: 2 | L20: =COUNTIF('Movie Data Base by Keizar'!G:G,K20) -> 16
A21: Bélico | B21: =COUNTIF('Movie Data Base by Keizar'!J:J,A21) -> 81 | C21: =COUNTIFS('Movie Data Base by Keizar'!J:J,A21,'Movie Data Base by Keizar'!G:G,">0") -> 22 | D21: =IFERROR(ROUND(AVERAGEIFS('Movie Data Base by Keizar'!G:G,'Movie Data Base by Keizar'!J:J,A21,'Movie Data Base by Keizar'!G:G,">0"),2),"") -> 7.14 | F21: 2010s | G21: =COUNTIF('Movie Data Base by Keizar'!C:C,F21) -> 759 | H21: =COUNTIFS('Movie Data Base by Keizar'!C:C,F21,'Movie Data Base by Keizar'!G:G,">0") -> 522 | I21: =IFERROR(ROUND(AVERAGEIFS('Movie Data Base by Keizar'!G:G,'Movie Data Base by Keizar'!C:C,F21,'Movie Data Base by Keizar'!G:G,">0"),2),"") -> 5.92 | K21: 1 | L21: =COUNTIF('Movie Data Base by Keizar'!G:G,K21) -> 5
A22: Musical | B22: =COUNTIF('Movie Data Base by Keizar'!J:J,A22) -> 79 | C22: =COUNTIFS('Movie Data Base by Keizar'!J:J,A22,'Movie Data Base by Keizar'!G:G,">0") -> 26 | D22: =IFERROR(ROUND(AVERAGEIFS('Movie Data Base by Keizar'!G:G,'Movie Data Base by Keizar'!J:J,A22,'Movie Data Base by Keizar'!G:G,">0"),2),"") -> 6.15 | F22: 2020s | G22: =COUNTIF('Movie Data Base by Keizar'!C:C,F22) -> 239 | H22: =COUNTIFS('Movie Data Base by Keizar'!C:C,F22,'Movie Data Base by Keizar'!G:G,">0") -> 123 | I22: =IFERROR(ROUND(AVERAGEIFS('Movie Data Base by Keizar'!G:G,'Movie Data Base by Keizar'!C:C,F22,'Movie Data Base by Keizar'!G:G,">0"),2),"") -> 6.14
A23: Aventura | B23: =COUNTIF('Movie Data Base by Keizar'!J:J,A23) -> 58 | C23: =COUNTIFS('Movie Data Base by Keizar'!J:J,A23,'Movie Data Base by Keizar'!G:G,">0") -> 29 | D23: =IFERROR(ROUND(AVERAGEIFS('Movie Data Base by Keizar'!G:G,'Movie Data Base by Keizar'!J:J,A23,'Movie Data Base by Keizar'!G:G,">0"),2),"") -> 6.17
A24: Documental | B24: =COUNTIF('Movie Data Base by Keizar'!J:J,A24) -> 33 | C24: =COUNTIFS('Movie Data Base by Keizar'!J:J,A24,'Movie Data Base by Keizar'!G:G,">0") -> 14 | D24: =IFERROR(ROUND(AVERAGEIFS('Movie Data Base by Keizar'!G:G,'Movie Data Base by Keizar'!J:J,A24,'Movie Data Base by Keizar'!G:G,">0"),2),"") -> 6.57
A25: Western | B25: =COUNTIF('Movie Data Base by Keizar'!J:J,A25) -> 19 | C25: =COUNTIFS('Movie Data Base by Keizar'!J:J,A25,'Movie Data Base by Keizar'!G:G,">0") -> 6 | D25: =IFERROR(ROUND(AVERAGEIFS('Movie Data Base by Keizar'!G:G,'Movie Data Base by Keizar'!J:J,A25,'Movie Data Base by Keizar'!G:G,">0"),2),"") -> 7.5
A30: PAÍSES MÁS VISTOS | F30: CANON PENDIENTE
A31: País | B31: En lista | C31: Vistas | F31: Sight & Sound: en lista | G31: =COUNT('Movie Data Base by Keizar'!T2:T4000) -> 253
A32: EE.UU. | B32: =COUNTIF('Movie Data Base by Keizar'!I:I,"*"&A32&"*") -> 1415 | C32: =COUNTIFS('Movie Data Base by Keizar'!I:I,"*"&A32&"*",'Movie Data Base by Keizar'!G:G,">0") -> 1047 | F32: Sight & Sound: vistas | G32: =COUNTIFS('Movie Data Base by Keizar'!T2:T4000,">0",'Movie Data Base by Keizar'!G2:G4000,">0") -> 29
A33: Reino Unido | B33: =COUNTIF('Movie Data Base by Keizar'!I:I,"*"&A33&"*") -> 297 | C33: =COUNTIFS('Movie Data Base by Keizar'!I:I,"*"&A33&"*",'Movie Data Base by Keizar'!G:G,">0") -> 174 | F33: Ranking J.Wild: en lista | G33: =COUNTA('Movie Data Base by Keizar'!V2:V4000) -> 449
A34: Francia | B34: =COUNTIF('Movie Data Base by Keizar'!I:I,"*"&A34&"*") -> 299 | C34: =COUNTIFS('Movie Data Base by Keizar'!I:I,"*"&A34&"*",'Movie Data Base by Keizar'!G:G,">0") -> 73 | F34: Ranking J.Wild: vistas | G34: =COUNTIFS('Movie Data Base by Keizar'!V2:V4000,"<>",'Movie Data Base by Keizar'!G2:G4000,">0") -> 100
A35: España | B35: =COUNTIF('Movie Data Base by Keizar'!I:I,"*"&A35&"*") -> 195 | C35: =COUNTIFS('Movie Data Base by Keizar'!I:I,"*"&A35&"*",'Movie Data Base by Keizar'!G:G,">0") -> 110 | F35: Top 150 XXI: vistas | G35: =COUNTIFS('Movie Data Base by Keizar'!W2:W4000,">0",'Movie Data Base by Keizar'!G2:G4000,">0") -> 0
A36: Alemania | B36: =COUNTIF('Movie Data Base by Keizar'!I:I,"*"&A36&"*") -> 186 | C36: =COUNTIFS('Movie Data Base by Keizar'!I:I,"*"&A36&"*",'Movie Data Base by Keizar'!G:G,">0") -> 91
A37: Japón | B37: =COUNTIF('Movie Data Base by Keizar'!I:I,"*"&A37&"*") -> 112 | C37: =COUNTIFS('Movie Data Base by Keizar'!I:I,"*"&A37&"*",'Movie Data Base by Keizar'!G:G,">0") -> 21
A38: Italia | B38: =COUNTIF('Movie Data Base by Keizar'!I:I,"*"&A38&"*") -> 97 | C38: =COUNTIFS('Movie Data Base by Keizar'!I:I,"*"&A38&"*",'Movie Data Base by Keizar'!G:G,">0") -> 25
A39: Canadá | B39: =COUNTIF('Movie Data Base by Keizar'!I:I,"*"&A39&"*") -> 89 | C39: =COUNTIFS('Movie Data Base by Keizar'!I:I,"*"&A39&"*",'Movie Data Base by Keizar'!G:G,">0") -> 62
A40: Corea del Sur | B40: =COUNTIF('Movie Data Base by Keizar'!I:I,"*"&A40&"*") -> 36 | C40: =COUNTIFS('Movie Data Base by Keizar'!I:I,"*"&A40&"*",'Movie Data Base by Keizar'!G:G,">0") -> 8
A41: China | B41: =COUNTIF('Movie Data Base by Keizar'!I:I,"*"&A41&"*") -> 42 | C41: =COUNTIFS('Movie Data Base by Keizar'!I:I,"*"&A41&"*",'Movie Data Base by Keizar'!G:G,">0") -> 23
A42: Argentina | B42: =COUNTIF('Movie Data Base by Keizar'!I:I,"*"&A42&"*") -> 44 | C42: =COUNTIFS('Movie Data Base by Keizar'!I:I,"*"&A42&"*",'Movie Data Base by Keizar'!G:G,">0") -> 10
A43: Dinamarca | B43: =COUNTIF('Movie Data Base by Keizar'!I:I,"*"&A43&"*") -> 35 | C43: =COUNTIFS('Movie Data Base by Keizar'!I:I,"*"&A43&"*",'Movie Data Base by Keizar'!G:G,">0") -> 3
A44: Australia | B44: =COUNTIF('Movie Data Base by Keizar'!I:I,"*"&A44&"*") -> 30 | C44: =COUNTIFS('Movie Data Base by Keizar'!I:I,"*"&A44&"*",'Movie Data Base by Keizar'!G:G,">0") -> 24
A45: México | B45: =COUNTIF('Movie Data Base by Keizar'!I:I,"*"&A45&"*") -> 22 | C45: =COUNTIFS('Movie Data Base by Keizar'!I:I,"*"&A45&"*",'Movie Data Base by Keizar'!G:G,">0") -> 7
A60: CÓMO LEER LOS COLORES
...
